Workbook

Sheet Data Residual
A1: DATA RESIDUAL
A2: No | B2: Residual (e)
A3: 1 | B3: 33.7373
A4: 2 | B4: 4.3311
A5: 3 | B5: 148.1852
A6: 4 | B6: -29.552
A7: 5 | B7: -122.8664
A8: 6 | B8: -66.2055
A9: 7 | B9: -150.8538
A10: 8 | B10: 24.801
A11: 9 | B11: -68.0828
A12: 10 | B12: -79.7531
A13: 11 | B13: 23.0951
A14: 12 | B14: 42.0103
... A54: 52 | B54: -16.8045

Sheet Uji KS
A1: UJI NORMALITAS KOLMOGOROV-SMIRNOV
A3: N (Jumlah Data) | H3: =COUNTA('Data Residual'!B3:B54) -> 52
A4: Rata-rata (μ) | H4: =AVERAGE('Data Residual'!B3:B54) -> -0.73586538
A5: Std. Deviasi (σ) | H5: =STDEV('Data Residual'!B3:B54) -> 65.757493
A7: No | B7: X(i) Terurut | C7: Z = (Xi-μ)/σ | D7: F(Z) = NORMSDIST | E7: Fn(x) = i/n | F7: Fn(x) = (i-1)/n | G7: |i/n − F(Z)| | H7: |(i-1)/n − F(Z)| | I7: D = MAX
A8: 1 | B8: =SMALL('Data Residual'!$B$3:$B$54,1) -> -150.8538 | C8: =(B8-$H$4)/$H$5 -> -2.2829023 | D8: =NORMSDIST(C8) -> 0.011218061 | E8: =1/$H$3 -> 0.019230769 | F8: =0/$H$3 -> 0 | G8: =ABS(E8-D8) -> 0.0080127086 | H8: =ABS(F8-D8) -> 0.011218061 | I8: =MAX(G8,H8) -> 0.011218061
A9: 2 | B9: =SMALL('Data Residual'!$B$3:$B$54,2) -> -140.5157 | C9: =(B9-$H$4)/$H$5 -> -2.1256868 | D9: =NORMSDIST(C9) -> 0.016764673 | E9: =2/$H$3 -> 0.038461538 | F9: =1/$H$3 -> 0.019230769 | G9: =ABS(E9-D9) -> 0.021696865 | H9: =ABS(F9-D9) -> 0.0024660959 | I9: =MAX(G9,H9) -> 0.021696865
A10: 3 | B10: =SMALL('Data Residual'!$B$3:$B$54,3) -> -122.8664 | C10: =(B10-$H$4)/$H$5 -> -1.857287 | D10: =NORMSDIST(C10) -> 0.031635169 | E10: =3/$H$3 -> 0.057692308 | F10: =2/$H$3 -> 0.038461538 | G10: =ABS(E10-D10) -> 0.026057139 | H10: =ABS(F10-D10) -> 0.0068263699 | I10: =MAX(G10,H10) -> 0.026057139
A11: 4 | B11: =SMALL('Data Residual'!$B$3:$B$54,4) -> -88.799 | C11: =(B11-$H$4)/$H$5 -> -1.3392106 | D11: =NORMSDIST(C11) -> 0.090251053 | E11: =4/$H$3 -> 0.076923077 | F11: =3/$H$3 -> 0.057692308 | G11: =ABS(E11-D11) -> 0.013327976 | H11: =ABS(F11-D11) -> 0.032558746 | I11: =MAX(G11,H11) -> 0.032558746
A12: 5 | B12: =SMALL('Data Residual'!$B$3:$B$54,5) -> -79.7531 | C12: =(B12-$H$4)/$H$5 -> -1.2016461 | D12: =NORMSDIST(C12) -> 0.11475034 | E12: =5/$H$3 -> 0.096153846 | F12: =4/$H$3 -> 0.076923077 | G12: =ABS(E12-D12) -> 0.018596491 | H12: =ABS(F12-D12) -> 0.03782726 | I12: =MAX(G12,H12) -> 0.03782726
A13: 6 | B13: =SMALL('Data Residual'!$B$3:$B$54,6) -> -74.3323 | C13: =(B13-$H$4)/$H$5 -> -1.1192099 | D13: =NORMSDIST(C13) -> 0.13152531 | E13: =6/$H$3 -> 0.11538462 | F13: =5/$H$3 -> 0.096153846 | G13: =ABS(E13-D13) -> 0.016140694 | H13: =ABS(F13-D13) -> 0.035371463 | I13: =MAX(G13,H13) -> 0.035371463
A14: 7 | B14: =SMALL('Data Residual'!$B$3:$B$54,7) -> -68.0828 | C14: =(B14-$H$4)/$H$5 -> -1.0241713 | D14: =NORMSDIST(C14) -> 0.15287719 | E14: =7/$H$3 -> 0.13461538 | F14: =6/$H$3 -> 0.11538462 | G14: =ABS(E14-D14) -> 0.01826181 | H14: =ABS(F14-D14) -> 0.037492579 | I14: =MAX(G14,H14) -> 0.037492579
A15: 8 | B15: =SMALL('Data Residual'!$B$3:$B$54,8) -> -67.2651 | C15: =(B15-$H$4)/$H$5 -> -1.0117362 | D15: =NORMSDIST(C15) -> 0.15583211 | E15: =8/$H$3 -> 0.15384615 | F15: =7/$H$3 -> 0.13461538 | G15: =ABS(E15-D15) -> 0.0019859519 | H15: =ABS(F15-D15) -> 0.021216721 | I15: =MAX(G15,H15) -> 0.021216721
A16: 9 | B16: =SMALL('Data Residual'!$B$3:$B$54,9) -> -66.2055 | C16: =(B16-$H$4)/$H$5 -> -0.99562243 | D16: =NORMSDIST(C16) -> 0.15971682 | E16: =9/$H$3 -> 0.17307692 | F16: =8/$H$3 -> 0.15384615 | G16: =ABS(E16-D16) -> 0.013360106 | H16: =ABS(F16-D16) -> 0.0058706629 | I16: =MAX(G16,H16) -> 0.013360106
A17: 10 | B17: =SMALL('Data Residual'!$B$3:$B$54,10) -> -63.0268 | C17: =(B17-$H$4)/$H$5 -> -0.94728269 | D17: =NORMSDIST(C17) -> 0.17174737 | E17: =10/$H$3 -> 0.19230769 | F17: =9/$H$3 -> 0.17307692 | G17: =ABS(E17-D17) -> 0.020560318 | H17: =ABS(F17-D17) -> 0.0013295483 | I17: =MAX(G17,H17) -> 0.020560318
A18: 11 | B18: =SMALL('Data Residual'!$B$3:$B$54,11) -> -52.9959 | C18: =(B18-$H$4)/$H$5 -> -0.79473886 | D18: =NORMSDIST(C18) -> 0.21338271 | E18: =11/$H$3 -> 0.21153846 | F18: =10/$H$3 -> 0.19230769 | G18: =ABS(E18-D18) -> 0.0018442509 | H18: =ABS(F18-D18) -> 0.02107502 | I18: =MAX(G18,H18) -> 0.02107502
A19: 12 | B19: =SMALL('Data Residual'!$B$3:$B$54,12) -> -48.9335 | C19: =(B19-$H$4)/$H$5 -> -0.73296034 | D19: =NORMSDIST(C19) -> 0.23179131 | E19: =12/$H$3 -> 0.23076923 | F19: =11/$H$3 -> 0.21153846 | G19: =ABS(E19-D19) -> 0.0010220772 | H19: =ABS(F19-D19) -> 0.020252846 | I19: =MAX(G19,H19) -> 0.020252846
A20: 13 | B20: =SMALL('Data Residual'!$B$3:$B$54,13) -> -42.0772 | C20: =(B20-$H$4)/$H$5 -> -0.6286939 | D20: =NORMSDIST(C20) -> 0.26477474 | E20: =13/$H$3 -> 0.25 | F20: =12/$H$3 -> 0.23076923 | G20: =ABS(E20-D20) -> 0.014774736 | H20: =ABS(F20-D20) -> 0.034005505 | I20: =MAX(G20,H20) -> 0.034005505
A21: 14 | B21: =SMALL('Data Residual'!$B$3:$B$54,14) -> -29.552 | C21: =(B21-$H$4)/$H$5 -> -0.43821827 | D21: =NORMSDIST(C21) -> 0.33061403 | E21: =14/$H$3 -> 0.26923077 | F21: =13/$H$3 -> 0.25 | G21: =ABS(E21-D21) -> 0.061383264 | H21: =ABS(F21-D21) -> 0.080614034 | I21: =MAX(G21,H21) -> 0.080614034
A22: 15 | B22: =SMALL('Data Residual'!$B$3:$B$54,15) -> -28.0908 | C22: =(B22-$H$4)/$H$5 -> -0.41599723 | D22: =NORMSDIST(C22) -> 0.33870602 | E22: =15/$H$3 -> 0.28846154 | F22: =14/$H$3 -> 0.26923077 | G22: =ABS(E22-D22) -> 0.050244478 | H22: =ABS(F22-D22) -> 0.069475247 | I22: =MAX(G22,H22) -> 0.069475247
A23: 16 | B23: =SMALL('Data Residual'!$B$3:$B$54,16) -> -27.866 | C23: =(B23-$H$4)/$H$5 -> -0.4125786 | D23: =NORMSDIST(C23) -> 0.33995769 | E23: =16/$H$3 -> 0.30769231 | F23: =15/$H$3 -> 0.28846154 | G23: =ABS(E23-D23) -> 0.032265382 | H23: =ABS(F23-D23) -> 0.051496151 | I23: =MAX(G23,H23) -> 0.051496151
A24: 17 | B24: =SMALL('Data Residual'!$B$3:$B$54,17) -> -24.5323 | C24: =(B24-$H$4)/$H$5 -> -0.36188172 | D24: =NORMSDIST(C24) -> 0.35872021 | E24: =17/$H$3 -> 0.32692308 | F24: =16/$H$3 -> 0.30769231 | G24: =ABS(E24-D24) -> 0.031797133 | H24: =ABS(F24-D24) -> 0.051027903 | I24: =MAX(G24,H24) -> 0.051027903
A25: 18 | B25: =SMALL('Data Residual'!$B$3:$B$54,18) -> -22.6349 | C25: =(B25-$H$4)/$H$5 -> -0.33302721 | D25: =NORMSDIST(C25) -> 0.36955687 | E25: =18/$H$3 -> 0.34615385 | F25: =17/$H$3 -> 0.32692308 | G25: =ABS(E25-D25) -> 0.023403024 | H25: =ABS(F25-D25) -> 0.042633794 | I25: =MAX(G25,H25) -> 0.042633794
A26: 19 | B26: =SMALL('Data Residual'!$B$3:$B$54,19) -> -22.3254 | C26: =(B26-$H$4)/$H$5 -> -0.32832053 | D26: =NORMSDIST(C26) -> 0.37133466 | E26: =19/$H$3 -> 0.36538462 | F26: =18/$H$3 -> 0.34615385 | G26: =ABS(E26-D26) -> 0.0059500477 | H26: =ABS(F26-D26) -> 0.025180817 | I26: =MAX(G26,H26) -> 0.025180817
A27: 20 | B27: =SMALL('Data Residual'!$B$3:$B$54,20) -> -21.775 | C27: =(B27-$H$4)/$H$5 -> -0.31995038 | D27: =NORMSDIST(C27) -> 0.37450297 | E27: =20/$H$3 -> 0.38461538 | F27: =19/$H$3 -> 0.36538462 | G27: =ABS(E27-D27) -> 0.010112411 | H27: =ABS(F27-D27) -> 0.0091183587 | I27: =MAX(G27,H27) -> 0.010112411
A28: 21 | B28: =SMALL('Data Residual'!$B$3:$B$54,21) -> -19.7532 | C28: =(B28-$H$4)/$H$5 -> -0.28920407 | D28: =NORMSDIST(C28) -> 0.38621261 | E28: =21/$H$3 -> 0.40384615 | F28: =20/$H$3 -> 0.38461538 | G28: =ABS(E28-D28) -> 0.017633545 | H28: =ABS(F28-D28) -> 0.0015972238 | I28: =MAX(G28,H28) -> 0.017633545
A29: 22 | B29: =SMALL('Data Residual'!$B$3:$B$54,22) -> -19.2385 | C29: =(B29-$H$4)/$H$5 -> -0.28137683 | D29: =NORMSDIST(C29) -> 0.3892107 | E29: =22/$H$3 -> 0.42307692 | F29: =21/$H$3 -> 0.40384615 | G29: =ABS(E29-D29) -> 0.033866228 | H29: =ABS(F29-D29) -> 0.014635459 | I29: =MAX(G29,H29) -> 0.033866228
A30: 23 | B30: =SMALL('Data Residual'!$B$3:$B$54,23) -> -17.9667 | C30: =(B30-$H$4)/$H$5 -> -0.26203606 | D30: =NORMSDIST(C30) -> 0.39664682 | E30: =23/$H$3 -> 0.44230769 | F30: =22/$H$3 -> 0.42307692 | G30: =ABS(E30-D30) -> 0.045660873 | H30: =ABS(F30-D30) -> 0.026430104 | I30: =MAX(G30,H30) -> 0.045660873
A31: 24 | B31: =SMALL('Data Residual'!$B$3:$B$54,24) -> -16.8045 | C31: =(B31-$H$4)/$H$5 -> -0.24436203 | D31: =NORMSDIST(C31) -> 0.40347522 | E31: =24/$H$3 -> 0.46153846 | F31: =23/$H$3 -> 0.44230769 | G31: =ABS(E31-D31) -> 0.05806324 | H31: =ABS(F31-D31) -> 0.03883247 | I31: =MAX(G31,H31) -> 0.05806324
A32: 25 | B32: =SMALL('Data Residual'!$B$3:$B$54,25) -> -15.6546 | C32: =(B32-$H$4)/$H$5 -> -0.22687505 | D32: =NORMSDIST(C32) -> 0.41026045 | E32: =25/$H$3 -> 0.48076923 | F32: =24/$H$3 -> 0.46153846 | G32: =ABS(E32-D32) -> 0.07050878 | H32: =ABS(F32-D32) -> 0.051278011 | I32: =MAX(G32,H32) -> 0.07050878
A33: 26 | B33: =SMALL('Data Residual'!$B$3:$B$54,26) -> -13.6245 | C33: =(B33-$H$4)/$H$5 -> -0.19600252 | D33: =NORMSDIST(C33) -> 0.42230409 | E33: =26/$H$3 -> 0.5 | F33: =25/$H$3 -> 0.48076923 | G33: =ABS(E33-D33) -> 0.077695905 | H33: =ABS(F33-D33) -> 0.058465136 | I33: =MAX(G33,H33) -> 0.077695905
A34: 27 | B34: =SMALL('Data Residual'!$B$3:$B$54,27) -> -10.1944 | C34: =(B34-$H$4)/$H$5 -> -0.14383965 | D34: =NORMSDIST(C34) -> 0.44281355 | E34: =27/$H$3 -> 0.51923077 | F34: =26/$H$3 -> 0.5 | G34: =ABS(E34-D34) -> 0.076417222 | H34: =ABS(F34-D34) -> 0.057186453 | I34: =MAX(G34,H34) -> 0.076417222
A35: 28 | B35: =SMALL('Data Residual'!$B$3:$B$54,28) -> -3.9655 | C35: =(B35-$H$4)/$H$5 -> -0.049114321 | D35: =NORMSDIST(C35) -> 0.4804141 | E35: =28/$H$3 -> 0.53846154 | F35: =27/$H$3 -> 0.51923077 | G35: =ABS(E35-D35) -> 0.058047443 | H35: =ABS(F35-D35) -> 0.038816674 | I35: =MAX(G35,H35) -> 0.058047443
A36: 29 | B36: =SMALL('Data Residual'!$B$3:$B$54,29) -> -0.9079 | C36: =(B36-$H$4)/$H$5 -> -0.0026161979 | D36: =NORMSDIST(C36) -> 0.49895629 | E36: =29/$H$3 -> 0.55769231 | F36: =28/$H$3 -> 0.53846154 | G36: =ABS(E36-D36) -> 0.058736018 | H36: =ABS(F36-D36) -> 0.039505249 | I36: =MAX(G36,H36) -> 0.058736018
A37: 30 | B37: =SMALL('Data Residual'!$B$3:$B$54,30) -> 1.1905 | C37: =(B37-$H$4)/$H$5 -> 0.029294994 | D37: =NORMSDIST(C37) -> 0.51168534 | E37: =30/$H$3 -> 0.57692308 | F37: =29/$H$3 -> 0.55769231 | G37: =ABS(E37-D37) -> 0.065237736 | H37: =ABS(F37-D37) -> 0.046006967 | I37: =MAX(G37,H37) -> 0.065237736
A38: 31 | B38: =SMALL('Data Residual'!$B$3:$B$54,31) -> 4.3311 | C38: =(B38-$H$4)/$H$5 -> 0.077055331 | D38: =NORMSDIST(C38) -> 0.53071024 | E38: =31/$H$3 -> 0.59615385 | F38: =30/$H$3 -> 0.57692308 | G38: =ABS(E38-D38) -> 0.06544361 | H38: =ABS(F38-D38) -> 0.046212841 | I38: =MAX(G38,H38) -> 0.06544361
A39: 32 | B39: =SMALL('Data Residual'!$B$3:$B$54,32) -> 9.5345 | C39: =(B39-$H$4)/$H$5 -> 0.15618548 | D39: =NORMSDIST(C39) -> 0.56205659 | E39: =32/$H$3 -> 0.61538462 | F39: =31/$H$3 -> 0.59615385 | G39: =ABS(E39-D39) -> 0.053328027 | H39: =ABS(F39-D39) -> 0.034097258 | I39: =MAX(G39,H39) -> 0.053328027
A40: 33 | B40: =SMALL('Data Residual'!$B$3:$B$54,33) -> 17.9381 | C40: =(B40-$H$4)/$H$5 -> 0.28398232 | D40: =NORMSDIST(C40) -> 0.61178804 | E40: =33/$H$3 -> 0.63461538 | F40: =32/$H$3 -> 0.61538462 | G40: =ABS(E40-D40) -> 0.022827349 | H40: =ABS(F40-D40) -> 0.0035965801 | I40: =MAX(G40,H40) -> 0.022827349
A41: 34 | B41: =SMALL('Data Residual'!$B$3:$B$54,34) -> 23.0951 | C41: =(B41-$H$4)/$H$5 -> 0.36240684 | D41: =NORMSDIST(C41) -> 0.64147599 | E41: =34/$H$3 -> 0.65384615 | F41: =33/$H$3 -> 0.63461538 | G41: =ABS(E41-D41) -> 0.012370167 | H41: =ABS(F41-D41) -> 0.0068606021 | I41: =MAX(G41,H41) -> 0.012370167
A42: 35 | B42: =SMALL('Data Residual'!$B$3:$B$54,35) -> 24.801 | C42: =(B42-$H$4)/$H$5 -> 0.38834913 | D42: =NORMSDIST(C42) -> 0.65112116 | E42: =35/$H$3 -> 0.67307692 | F42: =34/$H$3 -> 0.65384615 | G42: =ABS(E42-D42) -> 0.021955764 | H42: =ABS(F42-D42) -> 0.0027249944 | I42: =MAX(G42,H42) -> 0.021955764
...

Sheet Petunjuk
A1: PETUNJUK RUMUS – UJI NORMALITAS KS
A2: KOLOM | B2: RUMUS / KETERANGAN
A3: X(i) Terurut | B3: SMALL(range, i) — urutkan data terkecil ke terbesar
A4: Z = (X-mu)/sigma | B4: (X(i) - mu) / sigma — standardisasi ke distribusi normal
A5: F(Z) Teoritis | B5: NORMSDIST(Z) — nilai CDF distribusi normal standar
A6: i/n [Fn atas] | B6: i/n — proporsi kumulatif empiris batas atas
A7: (i-1)/n [Fn bawah] | B7: (i-1)/n — proporsi kumulatif empiris batas bawah
A8: |i/n - F(Z)| | B8: ABS(i/n - F(Z)) — selisih absolut batas atas
A9: |(i-1)/n - F(Z)| | B9: ABS((i-1)/n - F(Z)) — selisih absolut batas bawah
A10: D per baris | B10: MAX(|i/n-F(Z)|, |(i-1)/n-F(Z)|) — nilai D tiap observasi
A11: D Hitung | B11: MAX(kolom D) — statistik uji KS terbesar
A12: D Tabel alpha=0,05 | B12: 1,36 / SQRT(n) — nilai kritis pada signifikansi 5%
A13: D Tabel alpha=0,01 | B13: 1,628 / SQRT(n) — nilai kritis pada signifikansi 1%
... A16: Warna HITAM | B16: Hasil perhitungan formula Excel (otomatis)
